Workbook

Sheet Athena_BV
B1: Benchmarks | C1: Base | N1: Slice | Y1: Cncrt | AJ1: Slice+Cncrt
C2: Variant Results | D2: Tool Decision | I2: SR | K2: TVT | L2: AVT | M2: MVT | N2: Variant Results | O2: Tool Decision | T2: SR | V2: TVT | W2: AVT | X2: MVT | Y2: Variant Results | Z2: Tool Decision | AE2: SR | AG2: TVT | AH2: AVT | AI2: MVT | AJ2: Variant Results | AK2: Tool Decision | AP2: SR | AR2: TVT | AS2: AVT | AT2: MVT
A3: loop | B3: Adding_Subtracting_Zero_1_NT.c | C3: (FSE_Bitvector_Mode_Adding_Subtracting_Zero_1_NT_Loop0_TestCase0, NO, 4937) | D3: correct | E3: 0 | F3: 0/0 | G3: 1 | H3: 1/1 | I3: 1 | J3: 1/1 | K3: 4937 | L3: 4937 | M3: 4937 | N3: (FSE_Bitvector_Mode_Adding_Subtracting_Zero_1_NT_Loop17_TestCase0, NO, 1969) | O3: correct | P3: 0 | Q3: 0/0 | R3: 1 | S3: 1/1 | T3: 1 | U3: 1/1 | V3: 1969 | W3: 1969 | X3: 1969 | Y3: (FSE_Bitvector_Mode_Adding_Subtracting_Zero_1_NT_Loop0_TestCase2, YES, 1692) (FSE_Bitvector_Mode_Adding_Subtracting_Zero_1_NT_Loop0_TestCase3, YES, 1711) (FSE_Bitvector_Mode_Adding_Subtracting_Zero_1_NT_Loop0_TestCase1, YES, 1679) (FSE_Bitvector_Mode_Adding_Subtracting_Zero_1_NT_Loop0_TestCase4, YES, 1672) (FSE_Bitvector_Mode_Adding_Subtracting_Zero_1_NT_Loop0_TestCase5, YES, 1799) (FSE_Bitvector_Mode_Adding_Subtracting_Zero_1_NT_Loop0_TestCase7, NO, 1686) (FSE_Bitvector_Mode_Adding_Subtracting_Zero_1_NT_Loop0_TestCase6, NO, 2021) (FSE_Bitvector_Mode_Adding_Subtracting_Zero_1_NT_Loop0_TestCase10, NO, 1712) (FSE_Bitvector_Mode_Adding_Subtracting_Zero_1_NT_Loop0_TestCase8, NO, 1734) (FSE_Bitvector_Mode_Adding_Subtracting_Zero_1_NT_Loop0_TestCase9, NO, 1714) | Z3: correct | AA3: 1 | AB3: 5/5 | AC3: 1 | AD3: 5/5 | AE3: 1 | AF3: 10/10 | AG3: 17420 | AH3: 1742 | AI3: 1711.5 | AJ3: (FSE_Bitvector_Mode_Adding_Subtracting_Zero_1_NT_Loop17_TestCase8, NO, 1664) (FSE_Bitvector_Mode_Adding_Subtracting_Zero_1_NT_Loop17_TestCase9, NO, 1707) (FSE_Bitvector_Mode_Adding_Subtracting_Zero_1_NT_Loop17_TestCase1, YES, 1937) (FSE_Bitvector_Mode_Adding_Subtracting_Zero_1_NT_Loop17_TestCase10, NO, 1759) (FSE_Bitvector_Mode_Adding_Subtracting_Zero_1_NT_Loop17_TestCase2, YES, 1743) (FSE_Bitvector_Mode_Adding_Subtracting_Zero_1_NT_Loop17_TestCase3, YES, 1710) (FSE_Bitvector_Mode_Adding_Subtracting_Zero_1_NT_Loop17_TestCase7, NO, 1736) (FSE_Bitvector_Mode_Adding_Subtracting_Zero_1_NT_Loop17_TestCase6, NO, 1726) (FSE_Bitvector_Mode_Adding_Subtracting_Zero_1_NT_Loop17_TestCase4, YES, 1709) (FSE_Bitvector_Mode_Adding_Subtracting_Zero_1_NT_Loop17_TestCase5, YES, 1870) | AK3: correct | AL3: 1 | AM3: 5/5 | AN3: 1 | AO3: 5/5 | AP3: 1 | AQ3: 10/10 | AR3: 17561 | AS3: 1756.1 | AT3: 1731
B4: Adding_Subtracting_Zero_1_T.c | C4: (FSE_Bitvector_Mode_Adding_Subtracting_Zero_1_T_Loop0_TestCase0, YES, 1935) | D4: correct | E4: 1 | F4: 1/1 | I4: 1 | J4: 1/1 | K4: 1935 | L4: 1935 | M4: 1935 | N4: (FSE_Bitvector_Mode_Adding_Subtracting_Zero_1_T_Loop17_TestCase0, YES, 1894) | O4: correct | P4: 1 | Q4: 1/1 | T4: 1 | U4: 1/1 | V4: 1894 | W4: 1894 | X4: 1894 | Y4: (FSE_Bitvector_Mode_Adding_Subtracting_Zero_1_T_Loop0_TestCase7, YES, 1713) (FSE_Bitvector_Mode_Adding_Subtracting_Zero_1_T_Loop0_TestCase6, YES, 1694) (FSE_Bitvector_Mode_Adding_Subtracting_Zero_1_T_Loop0_TestCase4, YES, 1696) (FSE_Bitvector_Mode_Adding_Subtracting_Zero_1_T_Loop0_TestCase5, YES, 1794) (FSE_Bitvector_Mode_Adding_Subtracting_Zero_1_T_Loop0_TestCase1, YES, 1687) (FSE_Bitvector_Mode_Adding_Subtracting_Zero_1_T_Loop0_TestCase2, YES, 1674) (FSE_Bitvector_Mode_Adding_Subtracting_Zero_1_T_Loop0_TestCase3, YES, 1676) (FSE_Bitvector_Mode_Adding_Subtracting_Zero_1_T_Loop0_TestCase10, YES, 1676) (FSE_Bitvector_Mode_Adding_Subtracting_Zero_1_T_Loop0_TestCase8, YES, 1677) (FSE_Bitvector_Mode_Adding_Subtracting_Zero_1_T_Loop0_TestCase9, YES, 1682) | Z4: correct | AA4: 1 | AB4: 10/10 | AE4: 1 | AF4: 10/10 | AG4: 16969 | AH4: 1696.9 | AI4: 1684.5 | AJ4: (FSE_Bitvector_Mode_Adding_Subtracting_Zero_1_T_Loop17_TestCase7, YES, 1707) (FSE_Bitvector_Mode_Adding_Subtracting_Zero_1_T_Loop17_TestCase6, YES, 1745) (FSE_Bitvector_Mode_Adding_Subtracting_Zero_1_T_Loop17_TestCase4, YES, 1973) (FSE_Bitvector_Mode_Adding_Subtracting_Zero_1_T_Loop17_TestCase5, YES, 1807) (FSE_Bitvector_Mode_Adding_Subtracting_Zero_1_T_Loop17_TestCase1, YES, 1753) (FSE_Bitvector_Mode_Adding_Subtracting_Zero_1_T_Loop17_TestCase2, YES, 1723) (FSE_Bitvector_Mode_Adding_Subtracting_Zero_1_T_Loop17_TestCase3, YES, 1752) (FSE_Bitvector_Mode_Adding_Subtracting_Zero_1_T_Loop17_TestCase10, YES, 1737) (FSE_Bitvector_Mode_Adding_Subtracting_Zero_1_T_Loop17_TestCase8, YES, 1747) (FSE_Bitvector_Mode_Adding_Subtracting_Zero_1_T_Loop17_TestCase9, YES, 1737) | AK4: correct | AL4: 1 | AM4: 10/10 | AP4: 1 | AQ4: 10/10 | AR4: 17681 | AS4: 1768.1 | AT4: 1746
B5: Adding_Subtracting_Zero_2_NT.c | C5: (FSE_Bitvector_Mode_Adding_Subtracting_Zero_2_NT_Loop0_TestCase0, NO, 65646) | D5: correct | E5: 0 | F5: 0/0 | G5: 1 | H5: 1/1 | I5: 1 | J5: 1/1 | K5: 65646 | L5: 65646 | M5: 65646 | N5: (FSE_Bitvector_Mode_Adding_Subtracting_Zero_2_NT_Loop34_TestCase0, NO, 50185) | O5: correct | P5: 0 | Q5: 0/0 | R5: 1 | S5: 1/1 | T5: 1 | U5: 1/1 | V5: 50185 | W5: 50185 | X5: 50185 | Y5: (FSE_Bitvector_Mode_Adding_Subtracting_Zero_2_NT_Loop0_TestCase7, NO, 1723) (FSE_Bitvector_Mode_Adding_Subtracting_Zero_2_NT_Loop0_TestCase6, NO, 1710) (FSE_Bitvector_Mode_Adding_Subtracting_Zero_2_NT_Loop0_TestCase4, YES, 1772) (FSE_Bitvector_Mode_Adding_Subtracting_Zero_2_NT_Loop0_TestCase5, YES, 1745) (FSE_Bitvector_Mode_Adding_Subtracting_Zero_2_NT_Loop0_TestCase10, NO, 1743) (FSE_Bitvector_Mode_Adding_Subtracting_Zero_2_NT_Loop0_TestCase1, YES, 1784) (FSE_Bitvector_Mode_Adding_Subtracting_Zero_2_NT_Loop0_TestCase2, YES, 1712) (FSE_Bitvector_Mode_Adding_Subtracting_Zero_2_NT_Loop0_TestCase3, YES, 1734) (FSE_Bitvector_Mode_Adding_Subtracting_Zero_2_NT_Loop0_TestCase8, NO, 1718) (FSE_Bitvector_Mode_Adding_Subtracting_Zero_2_NT_Loop0_TestCase9, NO, 1808) | Z5: correct | AA5: 1 | AB5: 5/5 | AC5: 1 | AD5: 5/5 | AE5: 1 | AF5: 10/10 | AG5: 17449 | AH5: 1744.9 | AI5: 1738.5 | AJ5: (FSE_Bitvector_Mode_Adding_Subtracting_Zero_2_NT_Loop34_TestCase8, NO, 1736) (FSE_Bitvector_Mode_Adding_Subtracting_Zero_2_NT_Loop34_TestCase9, NO, 1787) (FSE_Bitvector_Mode_Adding_Subtracting_Zero_2_NT_Loop34_TestCase4, YES, 1762) (FSE_Bitvector_Mode_Adding_Subtracting_Zero_2_NT_Loop34_TestCase5, YES, 1735) (FSE_Bitvector_Mode_Adding_Subtracting_Zero_2_NT_Loop34_TestCase7, NO, 1737) (FSE_Bitvector_Mode_Adding_Subtracting_Zero_2_NT_Loop34_TestCase6, NO, 1750) (FSE_Bitvector_Mode_Adding_Subtracting_Zero_2_NT_Loop34_TestCase2, YES, 1778) (FSE_Bitvector_Mode_Adding_Subtracting_Zero_2_NT_Loop34_TestCase3, YES, 1753) (FSE_Bitvector_Mode_Adding_Subtracting_Zero_2_NT_Loop34_TestCase1, YES, 1761) (FSE_Bitvector_Mode_Adding_Subtracting_Zero_2_NT_Loop34_TestCase10, NO, 1742) | AK5: correct | AL5: 1 | AM5: 5/5 | AN5: 1 | AO5: 5/5 | AP5: 1 | AQ5: 10/10 | AR5: 17541 | AS5: 1754.1 | AT5: 1751.5
B6: Adding_Subtracting_Zero_2_T.c | C6: (FSE_Bitvector_Mode_Adding_Subtracting_Zero_2_T_Loop0_TestCase0, TIMEOUT, 301974) | D6: correct | E6: 0 | F6: 0/1 | I6: 0 | J6: 0/1 | K6: 0 | L6: 0 | M6: 0 | N6: (FSE_Bitvector_Mode_Adding_Subtracting_Zero_2_T_Loop35_TestCase0, TIMEOUT, 302098) | O6: correct | P6: 0 | Q6: 0/1 | T6: 0 | U6: 0/1 | V6: 0 | W6: 0 | X6: 0 | Y6: (FSE_Bitvector_Mode_Adding_Subtracting_Zero_2_T_Loop0_TestCase9, YES, 1727) (FSE_Bitvector_Mode_Adding_Subtracting_Zero_2_T_Loop0_TestCase8, YES, 1749) (FSE_Bitvector_Mode_Adding_Subtracting_Zero_2_T_Loop0_TestCase10, YES, 1740) (FSE_Bitvector_Mode_Adding_Subtracting_Zero_2_T_Loop0_TestCase3, YES, 1694) (FSE_Bitvector_Mode_Adding_Subtracting_Zero_2_T_Loop0_TestCase2, YES, 1711) (FSE_Bitvector_Mode_Adding_Subtracting_Zero_2_T_Loop0_TestCase1, YES, 1703) (FSE_Bitvector_Mode_Adding_Subtracting_Zero_2_T_Loop0_TestCase5, YES, 1721) (FSE_Bitvector_Mode_Adding_Subtracting_Zero_2_T_Loop0_TestCase4, YES, 1707) (FSE_Bitvector_Mode_Adding_Subtracting_Zero_2_T_Loop0_TestCase6, YES, 1706) (FSE_Bitvector_Mode_Adding_Subtracting_Zero_2_T_Loop0_TestCase7, YES, 1701) | Z6: correct | AA6: 1 | AB6: 10/10 | AE6: 1 | AF6: 10/10 | AG6: 17159 | AH6: 1715.9 | AI6: 1709 | AJ6: (FSE_Bitvector_Mode_Adding_Subtracting_Zero_2_T_Loop35_TestCase10, YES, 1776) (FSE_Bitvector_Mode_Adding_Subtracting_Zero_2_T_Loop35_TestCase9, YES, 1753) (FSE_Bitvector_Mode_Adding_Subtracting_Zero_2_T_Loop35_TestCase8, YES, 1819) (FSE_Bitvector_Mode_Adding_Subtracting_Zero_2_T_Loop35_TestCase5, YES, 1745) (FSE_Bitvector_Mode_Adding_Subtracting_Zero_2_T_Loop35_TestCase4, YES, 1748) (FSE_Bitvector_Mode_Adding_Subtracting_Zero_2_T_Loop35_TestCase6, YES, 1796) (FSE_Bitvector_Mode_Adding_Subtracting_Zero_2_T_Loop35_TestCase7, YES, 1777) (FSE_Bitvector_Mode_Adding_Subtracting_Zero_2_T_Loop35_TestCase3, YES, 1759) (FSE_Bitvector_Mode_Adding_Subtracting_Zero_2_T_Loop35_TestCase2, YES, 1718) (FSE_Bitvector_Mode_Adding_Subtracting_Zero_2_T_Loop35_TestCase1, YES, 1765) | AK6: correct | AL6: 1 | AM6: 10/10 | AP6: 1 | AQ6: 10/10 | AR6: 17656 | AS6: 1765.6 | AT6: 1762
B7: Adding_Subtracting_Zero_3_NT.c | C7: (FSE_Bitvector_Mode_Adding_Subtracting_Zero_3_NT_Loop0_TestCase0, TIMEOUT, 301752) | D7: correct | E7: 0 | F7: 0/0 | G7: 0 | H7: 0/1 | I7: 0 | J7: 0/1 | K7: 0 | L7: 0 | M7: 0 | N7: (FSE_Bitvector_Mode_Adding_Subtracting_Zero_3_NT_Loop40_TestCase0, TIMEOUT, 302108) (FSE_Bitvector_Mode_Adding_Subtracting_Zero_3_NT_Loop75_TestCase0, TIMEOUT, 302033) | O7: correct | P7: 0 | Q7: 0/0 | R7: 0 | S7: 0/2 | T7: 0 | U7: 0/2 | V7: 0 | W7: 0 | X7: 0 | Y7: (FSE_Bitvector_Mode_Adding_Subtracting_Zero_3_NT_Loop0_TestCase3, YES, 2195) (FSE_Bitvector_Mode_Adding_Subtracting_Zero_3_NT_Loop0_TestCase2, YES, 1768) (FSE_Bitvector_Mode_Adding_Subtracting_Zero_3_NT_Loop0_TestCase1, YES, 1801) (FSE_Bitvector_Mode_Adding_Subtracting_Zero_3_NT_Loop0_TestCase5, TIMEOUT, 301687) (FSE_Bitvector_Mode_Adding_Subtracting_Zero_3_NT_Loop0_TestCase4, YES, 210313) (FSE_Bitvector_Mode_Adding_Subtracting_Zero_3_NT_Loop0_TestCase6, NO, 1748) (FSE_Bitvector_Mode_Adding_Subtracting_Zero_3_NT_Loop0_TestCase7, NO, 1784) (FSE_Bitvector_Mode_Adding_Subtracting_Zero_3_NT_Loop0_TestCase9, NO, 1787) (FSE_Bitvector_Mode_Adding_Subtracting_Zero_3_NT_Loop0_TestCase8, NO, 1733) (FSE_Bitvector_Mode_Adding_Subtracting_Zero_3_NT_Loop0_TestCase10, NO, 1791) | Z7: correct | AA7: 0.8 | AB7: 4/5 | AC7: 1 | AD7: 5/5 | AE7: 0.9 | AF7: 9/10 | AG7: 224920 | AH7: 24991.11 | AI7: 1787 | AJ7: (FSE_Bitvector_Mode_Adding_Subtracting_Zero_3_NT_Loop75_TestCase9, NO, 1777) (FSE_Bitvector_Mode_Adding_Subtracting_Zero_3_NT_Loop75_TestCase8, NO, 1803) (FSE_Bitvector_Mode_Adding_Subtracting_Zero_3_NT_Loop75_TestCase10, NO, 2099) (FSE_Bitvector_Mode_Adding_Subtracting_Zero_3_NT_Loop40_TestCase2, YES, 1760) (FSE_Bitvector_Mode_Adding_Subtracting_Zero_3_NT_Loop40_TestCase3, YES, 2008) (FSE_Bitvector_Mode_Adding_Subtracting_Zero_3_NT_Loop40_TestCase1, YES, 1756) (FSE_Bitvector_Mode_Adding_Subtracting_Zero_3_NT_Loop40_TestCase4, TIMEOUT, 301743) (FSE_Bitvector_Mode_Adding_Subtracting_Zero_3_NT_Loop40_TestCase5, TIMEOUT, 301721) (FSE_Bitvector_Mode_Adding_Subtracting_Zero_3_NT_Loop40_TestCase7, NO, 1766) (FSE_Bitvector_Mode_Adding_Subtracting_Zero_3_NT_Loop40_TestCase6, NO, 1950) (FSE_Bitvector_Mode_Adding_Subtracting_Zero_3_NT_Loop40_TestCase8, NO, 1799) (FSE_Bitvector_Mode_Adding_Subtracting_Zero_3_NT_Loop40_TestCase9, NO, 1788) (FSE_Bitvector_Mode_Adding_Subtracting_Zero_3_NT_Loop75_TestCase5, TIMEOUT, 301955) (FSE_Bitvector_Mode_Adding_Subtracting_Zero_3_NT_Loop75_TestCase4, TIMEOUT, 301727) (FSE_Bitvector_Mode_Adding_Subtracting_Zero_3_NT_Loop75_TestCase6, NO, 1738) (FSE_Bitvector_Mode_Adding_Subtracting_Zero_3_NT_Loop75_TestCase7, NO, 1792) (FSE_Bitvector_Mode_Adding_Subtracting_Zero_3_NT_Loop75_TestCase3, YES, 2145) (FSE_Bitvector_Mode_Adding_Subtracting_Zero_3_NT_Loop75_TestCase2, YES, 1783) (FSE_Bitvector_Mode_Adding_Subtracting_Zero_3_NT_Loop40_TestCase10, NO, 1781) (FSE_Bitvector_Mode_Adding_Subtracting_Zero_3_NT_Loop75_TestCase1, YES, 1943) | AK7: correct | AL7: 0.6 | AM7: 6/10 | AN7: 1 | AO7: 9/9 | AP7: 0.75 | AQ7: 15/20 | AR7: 27589 | AS7: 1839.27 | AT7: 1788
B8: Adding_Subtracting_Zero_3_T.c | C8: (FSE_Bitvector_Mode_Adding_Subtracting_Zero_3_T_Loop0_TestCase0, TIMEOUT, 302032) | D8: correct | E8: 0 | F8: 0/1 | I8: 0 | J8: 0/1 | K8: 0 | L8: 0 | M8: 0 | N8: (FSE_Bitvector_Mode_Adding_Subtracting_Zero_3_T_Loop37_TestCase0, TIMEOUT, 302060) (FSE_Bitvector_Mode_Adding_Subtracting_Zero_3_T_Loop72_TestCase0, TIMEOUT, 302038) | O8: correct | P8: 0 | Q8: 0/2 | T8: 0 | U8: 0/2 | V8: 0 | W8: 0 | X8: 0 | Y8: (FSE_Bitvector_Mode_Adding_Subtracting_Zero_3_T_Loop0_TestCase1, YES, 1772) (FSE_Bitvector_Mode_Adding_Subtracting_Zero_3_T_Loop0_TestCase3, YES, 2310) (FSE_Bitvector_Mode_Adding_Subtracting_Zero_3_T_Loop0_TestCase2, YES, 1801) (FSE_Bitvector_Mode_Adding_Subtracting_Zero_3_T_Loop0_TestCase6, YES, 1880) (FSE_Bitvector_Mode_Adding_Subtracting_Zero_3_T_Loop0_TestCase7, YES, 1886) (FSE_Bitvector_Mode_Adding_Subtracting_Zero_3_T_Loop0_TestCase5, TIMEOUT, 301676) (FSE_Bitvector_Mode_Adding_Subtracting_Zero_3_T_Loop0_TestCase4, TIMEOUT, 301840) (FSE_Bitvector_Mode_Adding_Subtracting_Zero_3_T_Loop0_TestCase9, YES, 2099) (FSE_Bitvector_Mode_Adding_Subtracting_Zero_3_T_Loop0_TestCase8, YES, 1876) (FSE_Bitvector_Mode_Adding_Subtracting_Zero_3_T_Loop0_TestCase10, YES, 1892) | Z8: correct | AA8: 0.8 | AB8: 8/10 | AE8: 0.8 | AF8: 8/10 | AG8: 15516 | AH8: 1939.5 | AI8: 1883 | AJ8: (FSE_Bitvector_Mode_Adding_Subtracting_Zero_3_T_Loop37_TestCase3, YES, 2196) (FSE_Bitvector_Mode_Adding_Subtracting_Zero_3_T_Loop37_TestCase2, YES, 1811) (FSE_Bitvector_Mode_Adding_Subtracting_Zero_3_T_Loop37_TestCase1, YES, 1818) (FSE_Bitvector_Mode_Adding_Subtracting_Zero_3_T_Loop37_TestCase5, TIMEOUT, 302012) (FSE_Bitvector_Mode_Adding_Subtracting_Zero_3_T_Loop37_TestCase4, TIMEOUT, 301779) (FSE_Bitvector_Mode_Adding_Subtracting_Zero_3_T_Loop37_TestCase6, YES, 1824) (FSE_Bitvector_Mode_Adding_Subtracting_Zero_3_T_Loop37_TestCase7, YES, 1790) (FSE_Bitvector_Mode_Adding_Subtracting_Zero_3_T_Loop72_TestCase8, YES, 1897) (FSE_Bitvector_Mode_Adding_Subtracting_Zero_3_T_Loop72_TestCase9, YES, 1915) (FSE_Bitvector_Mode_Adding_Subtracting_Zero_3_T_Loop72_TestCase10, YES, 2010) (FSE_Bitvector_Mode_Adding_Subtracting_Zero_3_T_Loop72_TestCase7, YES, 2193) (FSE_Bitvector_Mode_Adding_Subtracting_Zero_3_T_Loop72_TestCase6, YES, 2210) (FSE_Bitvector_Mode_Adding_Subtracting_Zero_3_T_Loop72_TestCase4, TIMEOUT, 301929) (FSE_Bitvector_Mode_Adding_Subtracting_Zero_3_T_Loop72_TestCase5, TIMEOUT, 301746) (FSE_Bitvector_Mode_Adding_Subtracting_Zero_3_T_Loop37_TestCase10, YES, 1988) (FSE_Bitvector_Mode_Adding_Subtracting_Zero_3_T_Loop72_TestCase1, YES, 1865) (FSE_Bitvector_Mode_Adding_Subtracting_Zero_3_T_Loop72_TestCase2, YES, 1817) (FSE_Bitvector_Mode_Adding_Subtracting_Zero_3_T_Loop72_TestCase3, YES, 4378) (FSE_Bitvector_Mode_Adding_Subtracting_Zero_3_T_Loop37_TestCase9, YES, 1864) (FSE_Bitvector_Mode_Adding_Subtracting_Zero_3_T_Loop37_TestCase8, YES, 1816) | AK8: correct | AL8: 0.8 | AM8: 16/20 | AP8: 0.8 | AQ8: 16/20 | AR8: 33392 | AS8: 2087 | AT8: 1881
B9: Adding_Subtracting_Zero_4_NT.c | C9: (FSE_Bitvector_Mode_Adding_Subtracting_Zero_4_NT_Loop0_TestCase0, NO, 50487) | D9: correct | E9: 0 | F9: 0/0 | G9: 1 | H9: 1/1 | I9: 1 | J9: 1/1 | K9: 50487 | L9: 50487 | M9: 50487 | N9: (FSE_Bitvector_Mode_Adding_Subtracting_Zero_4_NT_Loop50_TestCase0, TIMEOUT, 302099) (FSE_Bitvector_Mode_Adding_Subtracting_Zero_4_NT_Loop16_TestCase0, TIMEOUT, 302078) | O9: correct | P9: 0 | Q9: 0/0 | R9: 0 | S9: 0/2 | T9: 0 | U9: 0/2 | V9: 0 | W9: 0 | X9: 0 | Y9: (FSE_Bitvector_Mode_Adding_Subtracting_Zero_4_NT_Loop0_TestCase1, YES, 1778) (FSE_Bitvector_Mode_Adding_Subtracting_Zero_4_NT_Loop0_TestCase3, YES, 19819) (FSE_Bitvector_Mode_Adding_Subtracting_Zero_4_NT_Loop0_TestCase2, YES, 1747) (FSE_Bitvector_Mode_Adding_Subtracting_Zero_4_NT_Loop0_TestCase6, NO, 1741) (FSE_Bitvector_Mode_Adding_Subtracting_Zero_4_NT_Loop0_TestCase7, NO, 1892) (FSE_Bitvector_Mode_Adding_Subtracting_Zero_4_NT_Loop0_TestCase5, YES, 16230) (FSE_Bitvector_Mode_Adding_Subtracting_Zero_4_NT_Loop0_TestCase4, YES, 46273) (FSE_Bitvector_Mode_Adding_Subtracting_Zero_4_NT_Loop0_TestCase9, NO, 1772) (FSE_Bitvector_Mode_Adding_Subtracting_Zero_4_NT_Loop0_TestCase8, NO, 1753) (FSE_Bitvector_Mode_Adding_Subtracting_Zero_4_NT_Loop0_TestCase10, NO, 1752) | Z9: correct | AA9: 1 | AB9: 5/5 | AC9: 1 | AD9: 5/5 | AE9: 1 | AF9: 10/10 | AG9: 94757 | AH9: 9475.7 | AI9: 1775 | AJ9: (FSE_Bitvector_Mode_Adding_Subtracting_Zero_4_NT_Loop50_TestCase4, YES, 116678) (FSE_Bitvector_Mode_Adding_Subtracting_Zero_4_NT_Loop50_TestCase5, YES, 48537) (FSE_Bitvector_Mode_Adding_Subtracting_Zero_4_NT_Loop50_TestCase7, NO, 2076) (FSE_Bitvector_Mode_Adding_Subtracting_Zero_4_NT_Loop50_TestCase6, NO, 1852) (FSE_Bitvector_Mode_Adding_Subtracting_Zero_4_NT_Loop50_TestCase2, YES, 1792) (FSE_Bitvector_Mode_Adding_Subtracting_Zero_4_NT_Loop50_TestCase10, NO, 1970) (FSE_Bitvector_Mode_Adding_Subtracting_Zero_4_NT_Loop50_TestCase3, YES, 19125) (FSE_Bitvector_Mode_Adding_Subtracting_Zero_4_NT_Loop50_TestCase1, YES, 1796) (FSE_Bitvector_Mode_Adding_Subtracting_Zero_4_NT_Loop16_TestCase9, NO, 2117) (FSE_Bitvector_Mode_Adding_Subtracting_Zero_4_NT_Loop16_TestCase8, NO, 2093) (FSE_Bitvector_Mode_Adding_Subtracting_Zero_4_NT_Loop16_TestCase5, TIMEOUT, 301728) (FSE_Bitvector_Mode_Adding_Subtracting_Zero_4_NT_Loop16_TestCase4, YES, 30315) (FSE_Bitvector_Mode_Adding_Subtracting_Zero_4_NT_Loop16_TestCase10, NO, 2180) (FSE_Bitvector_Mode_Adding_Subtracting_Zero_4_NT_Loop16_TestCase6, NO, 1835) (FSE_Bitvector_Mode_Adding_Subtracting_Zero_4_NT_Loop16_TestCase7, NO, 2151) (FSE_Bitvector_Mode_Adding_Subtracting_Zero_4_NT_Loop16_TestCase3, YES, 14038) (FSE_Bitvector_Mode_Adding_Subtracting_Zero_4_NT_Loop16_TestCase2, YES, 1750) (FSE_Bitvector_Mode_Adding_Subtracting_Zero_4_NT_Loop16_TestCase1, YES, 1813) (FSE_Bitvector_Mode_Adding_Subtracting_Zero_4_NT_Loop50_TestCase8, NO, 2116) (FSE_Bitvector_Mode_Adding_Subtracting_Zero_4_NT_Loop50_TestCase9, NO, 1791) | AK9: correct | AL9: 0.9 | AM9: 9/10 | AN9: 1 | AO9: 10/10 | AP9: 0.95 | AQ9: 19/20 | AR9: 256025 | AS9: 13475 | AT9: 2093
B10: Adding_Subtracting_Zero_4_T.c | C10: (FSE_Bitvector_Mode_Adding_Subtracting_Zero_4_T_Loop0_TestCase0, TIMEOUT, 302142) | D10: correct | E10: 0 | F10: 0/1 | I10: 0 | J10: 0/1 | K10: 0 | L10: 0 | M10: 0 | N10: (FSE_Bitvector_Mode_Adding_Subtracting_Zero_4_T_Loop16_TestCase0, TIMEOUT, 301970) (FSE_Bitvector_Mode_Adding_Subtracting_Zero_4_T_Loop51_TestCase0, TIMEOUT, 302016) | O10: correct | P10: 0 | Q10: 0/2 | T10: 0 | U10: 0/2 | V10: 0 | W10: 0 | X10: 0 | Y10: (FSE_Bitvector_Mode_Adding_Subtracting_Zero_4_T_Loop0_TestCase8, YES, 7726) (FSE_Bitvector_Mode_Adding_Subtracting_Zero_4_T_Loop0_TestCase9, YES, 11130) (FSE_Bitvector_Mode_Adding_Subtracting_Zero_4_T_Loop0_TestCase7, YES, 25459) (FSE_Bitvector_Mode_Adding_Subtracting_Zero_4_T_Loop0_TestCase6, YES, 8583) (FSE_Bitvector_Mode_Adding_Subtracting_Zero_4_T_Loop0_TestCase4, TIMEOUT, 301740) (FSE_Bitvector_Mode_Adding_Subtracting_Zero_4_T_Loop0_TestCase5, TIMEOUT, 301731) (FSE_Bitvector_Mode_Adding_Subtracting_Zero_4_T_Loop0_TestCase1, YES, 1945) (FSE_Bitvector_Mode_Adding_Subtracting_Zero_4_T_Loop0_TestCase10, YES, 14542) (FSE_Bitvector_Mode_Adding_Subtracting_Zero_4_T_Loop0_TestCase2, YES, 1792) (FSE_Bitvector_Mode_Adding_Subtracting_Zero_4_T_Loop0_TestCase3, YES, 62647) | Z10: correct | AA10: 0.8 | AB10: 8/10 | AE10: 0.8 | AF10: 8/10 | AG10: 133824 | AH10: 16728 | AI10: 9856.5 | AJ10: (FSE_Bitvector_Mode_Adding_Subtracting_Zero_4_T_Loop16_TestCase10, YES, 19334) (FSE_Bitvector_Mode_Adding_Subtracting_Zero_4_T_Loop51_TestCase8, YES, 51520) (FSE_Bitvector_Mode_Adding_Subtracting_Zero_4_T_Loop51_TestCase9, YES, 18988) (FSE_Bitvector_Mode_Adding_Subtracting_Zero_4_T_Loop16_TestCase8, YES, 10413) (FSE_Bitvector_Mode_Adding_Subtracting_Zero_4_T_Loop16_TestCase9, YES, 10502) (FSE_Bitvector_Mode_Adding_Subtracting_Zero_4_T_Loop16_TestCase2, YES, 1825) (FSE_Bitvector_Mode_Adding_Subtracting_Zero_4_T_Loop16_TestCase3, YES, 15376) (FSE_Bitvector_Mode_Adding_Subtracting_Zero_4_T_Loop16_TestCase1, YES, 2106) (FSE_Bitvector_Mode_Adding_Subtracting_Zero_4_T_Loop16_TestCase4, YES, 151966) (FSE_Bitvector_Mode_Adding_Subtracting_Zero_4_T_Loop16_TestCase5, TIMEOUT, 301772) (FSE_Bitvector_Mode_Adding_Subtracting_Zero_4_T_Loop51_TestCase10, YES, 16230) (FSE_Bitvector_Mode_Adding_Subtracting_Zero_4_T_Loop16_TestCase7, YES, 17018) (FSE_Bitvector_Mode_Adding_Subtracting_Zero_4_T_Loop16_TestCase6, YES, 6960) (FSE_Bitvector_Mode_Adding_Subtracting_Zero_4_T_Loop51_TestCase4, TIMEOUT, 301801) (FSE_Bitvector_Mode_Adding_Subtracting_Zero_4_T_Loop51_TestCase5, TIMEOUT, 301757) (FSE_Bitvector_Mode_Adding_Subtracting_Zero_4_T_Loop51_TestCase7, YES, 14042) (FSE_Bitvector_Mode_Adding_Subtracting_Zero_4_T_Loop51_TestCase6, YES, 5527) (FSE_Bitvector_Mode_Adding_Subtracting_Zero_4_T_Loop51_TestCase2, YES, 1857) (FSE_Bitvector_Mode_Adding_Subtracting_Zero_4_T_Loop51_TestCase3, YES, 51987) (FSE_Bitvector_Mode_Adding_Subtracting_Zero_4_T_Loop51_TestCase1, YES, 1790) | AK10: correct | AL10: 0.85 | AM10: 17/20 | AP10: 0.85 | AQ10: 17/20 | AR10: 397441 | AS10: 23378.88 | AT10: 14042
B11: Adding_Subtracting_Zero_5_NT.c | C11: (FSE_Bitvector_Mode_Adding_Subtracting_Zero_5_NT_Loop0_TestCase0, NO, 2684) | D11: correct | E11: 0 | F11: 0/0 | G11: 1 | H11: 1/1 | I11: 1 | J11: 1/1 | K11: 2684 | L11: 2684 | M11: 2684 | N11: (FSE_Bitvector_Mode_Adding_Subtracting_Zero_5_NT_Loop38_TestCase0, MAYBE, 1729) (FSE_Bitvector_Mode_Adding_Subtracting_Zero_5_NT_Loop21_TestCase0, MAYBE, 1373) | O11: correct | P11: 0 | Q11: 0/1 | R11: 0 | S11: 0/1 | T11: 0 | U11: 0/2 | V11: 0 | W11: 0 | X11: 0 | Y11: (FSE_Bitvector_Mode_Adding_Subtracting_Zero_5_NT_Loop0_TestCase4, YES, 2133) (FSE_Bitvector_Mode_Adding_Subtracting_Zero_5_NT_Loop0_TestCase5, YES, 1955) (FSE_Bitvector_Mode_Adding_Subtracting_Zero_5_NT_Loop0_TestCase7, TIMEOUT, 302020) (FSE_Bitvector_Mode_Adding_Subtracting_Zero_5_NT_Loop0_TestCase6, NO, 2320) (FSE_Bitvector_Mode_Adding_Subtracting_Zero_5_NT_Loop0_TestCase2, YES, 2154) (FSE_Bitvector_Mode_Adding_Subtracting_Zero_5_NT_Loop0_TestCase3, YES, 1956) (FSE_Bitvector_Mode_Adding_Subtracting_Zero_5_NT_Loop0_TestCase1, YES, 1979) (FSE_Bitvector_Mode_Adding_Subtracting_Zero_5_NT_Loop0_TestCase10, TIMEOUT, 301885) (FSE_Bitvector_Mode_Adding_Subtracting_Zero_5_NT_Loop0_TestCase8, TIMEOUT, 302017) (FSE_Bitvector_Mode_Adding_Subtracting_Zero_5_NT_Loop0_TestCase9, TIMEOUT, 301842) | Z11: correct | AA11: 1 | AB11: 5/5 | AC11: 0.2 | AD11: 1/5 | AE11: 0.6 | AF11: 6/10 | AG11: 12497 | AH11: 2082.83 | AI11: 2056 | AJ11: (FSE_Bitvector_Mode_Adding_Subtracting_Zero_5_NT_Loop38_TestCase1, MAYBE, 1494) (FSE_Bitvector_Mode_Adding_Subtracting_Zero_5_NT_Loop38_TestCase2, MAYBE, 1502) (FSE_Bitvector_Mode_Adding_Subtracting_Zero_5_NT_Loop38_TestCase10, MAYBE, 1716) (FSE_Bitvector_Mode_Adding_Subtracting_Zero_5_NT_Loop38_TestCase3, MAYBE, 1517) (FSE_Bitvector_Mode_Adding_Subtracting_Zero_5_NT_Loop38_TestCase7, MAYBE, 1540) (FSE_Bitvector_Mode_Adding_Subtracting_Zero_5_NT_Loop38_TestCase6, MAYBE, 1525) (FSE_Bitvector_Mode_Adding_Subtracting_Zero_5_NT_Loop38_TestCase4, MAYBE, 1496) (FSE_Bitvector_Mode_Adding_Subtracting_Zero_5_NT_Loop38_TestCase5, MAYBE, 1519) (FSE_Bitvector_Mode_Adding_Subtracting_Zero_5_NT_Loop21_TestCase4, MAYBE, 1353) (FSE_Bitvector_Mode_Adding_Subtracting_Zero_5_NT_Loop21_TestCase10, MAYBE, 1417) (FSE_Bitvector_Mode_Adding_Subtracting_Zero_5_NT_Loop21_TestCase5, MAYBE, 1337) (FSE_Bitvector_Mode_Adding_Subtracting_Zero_5_NT_Loop21_TestCase7, MAYBE, 1333) (FSE_Bitvector_Mode_Adding_Subtracting_Zero_5_NT_Loop21_TestCase6, MAYBE, 1343) (FSE_Bitvector_Mode_Adding_Subtracting_Zero_5_NT_Loop21_TestCase2, MAYBE, 1323) (FSE_Bitvector_Mode_Adding_Subtracting_Zero_5_NT_Loop21_TestCase3, MAYBE, 1348) (FSE_Bitvector_Mode_Adding_Subtracting_Zero_5_NT_Loop21_TestCase1, MAYBE, 1337) (FSE_Bitvector_Mode_Adding_Subtracting_Zero_5_NT_Loop21_TestCase8, MAYBE, 1318) (FSE_Bitvector_Mode_Adding_Subtracting_Zero_5_NT_Loop21_TestCase9, MAYBE, 1333) (FSE_Bitvector_Mode_Adding_Subtracting_Zero_5_NT_Loop38_TestCase8, MAYBE, 1512) (FSE_Bitvector_Mode_Adding_Subtracting_Zero_5_NT_Loop38_TestCase9, MAYBE, 1574) | AK11: correct | AL11: 0 | AM11: 0/15 | AN11: 0 | AO11: 0/5 | AP11: 0 | AQ11: 0/20 | AR11: 0 | AS11: 0 | AT11: 0 | AU11: Pointer + Structure
B12: Adding_Subtracting_Zero_5_T.c | C12: (FSE_Bitvector_Mode_Adding_Subtracting_Zero_5_T_Loop0_TestCase0, TIMEOUT, 302031) | D12: correct | E12: 0 | F12: 0/1 | I12: 0 | J12: 0/1 | K12: 0 | L12: 0 | M12: 0 | N12: (FSE_Bitvector_Mode_Adding_Subtracting_Zero_5_T_Loop21_TestCase0, MAYBE, 1400) (FSE_Bitvector_Mode_Adding_Subtracting_Zero_5_T_Loop38_TestCase0, MAYBE, 1573) | O12: correct | P12: 0 | Q12: 0/2 | T12: 0 | U12: 0/2 | V12: 0 | W12: 0 | X12: 0 | Y12: (FSE_Bitvector_Mode_Adding_Subtracting_Zero_5_T_Loop0_TestCase4, YES, 1982) (FSE_Bitvector_Mode_Adding_Subtracting_Zero_5_T_Loop0_TestCase5, YES, 2169) (FSE_Bitvector_Mode_Adding_Subtracting_Zero_5_T_Loop0_TestCase7, TIMEOUT, 302143) (FSE_Bitvector_Mode_Adding_Subtracting_Zero_5_T_Loop0_TestCase6, YES, 2063) (FSE_Bitvector_Mode_Adding_Subtracting_Zero_5_T_Loop0_TestCase2, YES, 2009) (FSE_Bitvector_Mode_Adding_Subtracting_Zero_5_T_Loop0_TestCase3, YES, 2108) (FSE_Bitvector_Mode_Adding_Subtracting_Zero_5_T_Loop0_TestCase1, YES, 1964) (FSE_Bitvector_Mode_Adding_Subtracting_Zero_5_T_Loop0_TestCase10, TIMEOUT, 301874) (FSE_Bitvector_Mode_Adding_Subtracting_Zero_5_T_Loop0_TestCase8, TIMEOUT, 301862) (FSE_Bitvector_Mode_Adding_Subtracting_Zero_5_T_Loop0_TestCase9, TIMEOUT, 302078) | Z12: correct | AA12: 0.6 | AB12: 6/10 | AE12: 0.6 | AF12: 6/10 | AG12: 12295 | AH12: 2049.17 | AI12: 2036 | AJ12: (FSE_Bitvector_Mode_Adding_Subtracting_Zero_5_T_Loop38_TestCase9, MAYBE, 1512) (FSE_Bitvector_Mode_Adding_Subtracting_Zero_5_T_Loop38_TestCase8, MAYBE, 1501) (FSE_Bitvector_Mode_Adding_Subtracting_Zero_5_T_Loop21_TestCase10, MAYBE, 1332) (FSE_Bitvector_Mode_Adding_Subtracting_Zero_5_T_Loop21_TestCase9, MAYBE, 1415) (FSE_Bitvector_Mode_Adding_Subtracting_Zero_5_T_Loop21_TestCase8, MAYBE, 1333) (FSE_Bitvector_Mode_Adding_Subtracting_Zero_5_T_Loop38_TestCase10, MAYBE, 1479) (FSE_Bitvector_Mode_Adding_Subtracting_Zero_5_T_Loop21_TestCase3, MAYBE, 1357) (FSE_Bitvector_Mode_Adding_Subtracting_Zero_5_T_Loop21_TestCase2, MAYBE, 1331) (FSE_Bitvector_Mode_Adding_Subtracting_Zero_5_T_Loop21_TestCase1, MAYBE, 1348) (FSE_Bitvector_Mode_Adding_Subtracting_Zero_5_T_Loop21_TestCase5, MAYBE, 1334) (FSE_Bitvector_Mode_Adding_Subtracting_Zero_5_T_Loop21_TestCase4, MAYBE, 1380) (FSE_Bitvector_Mode_Adding_Subtracting_Zero_5_T_Loop21_TestCase6, MAYBE, 1332) (FSE_Bitvector_Mode_Adding_Subtracting_Zero_5_T_Loop21_TestCase7, MAYBE, 1338) (FSE_Bitvector_Mode_Adding_Subtracting_Zero_5_T_Loop38_TestCase6, MAYBE, 1465) (FSE_Bitvector_Mode_Adding_Subtracting_Zero_5_T_Loop38_TestCase7, MAYBE, 1509) (FSE_Bitvector_Mode_Adding_Subtracting_Zero_5_T_Loop38_TestCase5, MAYBE, 1495) (FSE_Bitvector_Mode_Adding_Subtracting_Zero_5_T_Loop38_TestCase4, MAYBE, 1513) (FSE_Bitvector_Mode_Adding_Subtracting_Zero_5_T_Loop38_TestCase1, MAYBE, 1501) (FSE_Bitvector_Mode_Adding_Subtracting_Zero_5_T_Loop38_TestCase3, MAYBE, 1465) (FSE_Bitvector_Mode_Adding_Subtracting_Zero_5_T_Loop38_TestCase2, MAYBE, 1580) | AK12: correct | AL12: 0 | AM12: 0/20 | AP12: 0 | AQ12: 0/20 | AR12: 0 | AS12: 0 | AT12: 0 | AU12: Pointer + Structure
B13: Incorrect_Bit_Calculation_1_NT.c | C13: (FSE_Bitvector_Mode_Incorrect_Bit_Calculation_1_NT_Loop0_TestCase0, NO, 2060) | D13: correct | E13: 0 | F13: 0/0 | G13: 1 | H13: 1/1 | I13: 1 | J13: 1/1 | K13: 2060 | L13: 2060 | M13: 2060 | N13: (FSE_Bitvector_Mode_Incorrect_Bit_Calculation_1_NT_Loop15_TestCase0, NO, 1834) | O13: correct | P13: 0 | Q13: 0/0 | R13: 1 | S13: 1/1 | T13: 1 | U13: 1/1 | V13: 1834 | W13: 1834 | X13: 1834 | Y13: (FSE_Bitvector_Mode_Incorrect_Bit_Calculation_1_NT_Loop0_TestCase1, YES, 1692) (FSE_Bitvector_Mode_Incorrect_Bit_Calculation_1_NT_Loop0_TestCase2, YES, 1703) (FSE_Bitvector_Mode_Incorrect_Bit_Calculation_1_NT_Loop0_TestCase3, YES, 1714) (FSE_Bitvector_Mode_Incorrect_Bit_Calculation_1_NT_Loop0_TestCase7, NO, 1711) (FSE_Bitvector_Mode_Incorrect_Bit_Calculation_1_NT_Loop0_TestCase6, NO, 1718) (FSE_Bitvector_Mode_Incorrect_Bit_Calculation_1_NT_Loop0_TestCase10, NO, 1706) (FSE_Bitvector_Mode_Incorrect_Bit_Calculation_1_NT_Loop0_TestCase4, YES, 1705) (FSE_Bitvector_Mode_Incorrect_Bit_Calculation_1_NT_Loop0_TestCase5, YES, 1929) (FSE_Bitvector_Mode_Incorrect_Bit_Calculation_1_NT_Loop0_TestCase8, NO, 1699) (FSE_Bitvector_Mode_Incorrect_Bit_Calculation_1_NT_Loop0_TestCase9, NO, 1763) | Z13: correct | AA13: 1 | AB13: 5/5 | AC13: 1 | AD13: 5/5 | AE13: 1 | AF13: 10/10 | AG13: 17340 | AH13: 1734 | AI13: 1708.5 | AJ13: (FSE_Bitvector_Mode_Incorrect_Bit_Calculation_1_NT_Loop15_TestCase7, NO, 1875) (FSE_Bitvector_Mode_Incorrect_Bit_Calculation_1_NT_Loop15_TestCase6, NO, 1971) (FSE_Bitvector_Mode_Incorrect_Bit_Calculation_1_NT_Loop15_TestCase4, YES, 1723) (FSE_Bitvector_Mode_Incorrect_Bit_Calculation_1_NT_Loop15_TestCase5, YES, 2048) (FSE_Bitvector_Mode_Incorrect_Bit_Calculation_1_NT_Loop15_TestCase1, YES, 1719) (FSE_Bitvector_Mode_Incorrect_Bit_Calculation_1_NT_Loop15_TestCase2, YES, 1728) (FSE_Bitvector_Mode_Incorrect_Bit_Calculation_1_NT_Loop15_TestCase3, YES, 1715) (FSE_Bitvector_Mode_Incorrect_Bit_Calculation_1_NT_Loop15_TestCase10, NO, 1745) (FSE_Bitvector_Mode_Incorrect_Bit_Calculation_1_NT_Loop15_TestCase8, NO, 1734) (FSE_Bitvector_Mode_Incorrect_Bit_Calculation_1_NT_Loop15_TestCase9, NO, 1721) | AK13: correct | AL13: 1 | AM13: 5/5 | AN13: 1 | AO13: 5/5 | AP13: 1 | AQ13: 10/10 | AR13: 17979 | AS13: 1797.9 | AT13: 1731 | AU13: Bit Calculation
B14: Incorrect_Bit_Calculation_1_T.c | C14: (FSE_Bitvector_Mode_Incorrect_Bit_Calculation_1_T_Loop0_TestCase0, YES, 1792) | D14: correct | E14: 1 | F14: 1/1 | I14: 1 | J14: 1/1 | K14: 1792 | L14: 1792 | M14: 1792 | N14: (FSE_Bitvector_Mode_Incorrect_Bit_Calculation_1_T_Loop14_TestCase0, YES, 1764) | O14: correct | P14: 1 | Q14: 1/1 | T14: 1 | U14: 1/1 | V14: 1764 | W14: 1764 | X14: 1764 | Y14: (FSE_Bitvector_Mode_Incorrect_Bit_Calculation_1_T_Loop0_TestCase6, YES, 1700) (FSE_Bitvector_Mode_Incorrect_Bit_Calculation_1_T_Loop0_TestCase7, YES, 1691) (FSE_Bitvector_Mode_Incorrect_Bit_Calculation_1_T_Loop0_TestCase5, YES, 1726) (FSE_Bitvector_Mode_Incorrect_Bit_Calculation_1_T_Loop0_TestCase4, YES, 1707) (FSE_Bitvector_Mode_Incorrect_Bit_Calculation_1_T_Loop0_TestCase1, YES, 1688) (FSE_Bitvector_Mode_Incorrect_Bit_Calculation_1_T_Loop0_TestCase3, YES, 1699) (FSE_Bitvector_Mode_Incorrect_Bit_Calculation_1_T_Loop0_TestCase2, YES, 1688) (FSE_Bitvector_Mode_Incorrect_Bit_Calculation_1_T_Loop0_TestCase9, YES, 1718) (FSE_Bitvector_Mode_Incorrect_Bit_Calculation_1_T_Loop0_TestCase8, YES, 1719) (FSE_Bitvector_Mode_Incorrect_Bit_Calculation_1_T_Loop0_TestCase10, YES, 1664) | Z14: correct | AA14: 1 | AB14: 10/10 | AE14: 1 | AF14: 10/10 | AG14: 17000 | AH14: 1700 | AI14: 1699.5 | AJ14: (FSE_Bitvector_Mode_Incorrect_Bit_Calculation_1_T_Loop14_TestCase1, YES, 1840) (FSE_Bitvector_Mode_Incorrect_Bit_Calculation_1_T_Loop14_TestCase2, YES, 1747) (FSE_Bitvector_Mode_Incorrect_Bit_Calculation_1_T_Loop14_TestCase3, YES, 1721) (FSE_Bitvector_Mode_Incorrect_Bit_Calculation_1_T_Loop14_TestCase7, YES, 1722) (FSE_Bitvector_Mode_Incorrect_Bit_Calculation_1_T_Loop14_TestCase6, YES, 1727) (FSE_Bitvector_Mode_Incorrect_Bit_Calculation_1_T_Loop14_TestCase4, YES, 1967) (FSE_Bitvector_Mode_Incorrect_Bit_Calculation_1_T_Loop14_TestCase5, YES, 1741) (FSE_Bitvector_Mode_Incorrect_Bit_Calculation_1_T_Loop14_TestCase8, YES, 1715) (FSE_Bitvector_Mode_Incorrect_Bit_Calculation_1_T_Loop14_TestCase9, YES, 1714) (FSE_Bitvector_Mode_Incorrect_Bit_Calculation_1_T_Loop14_TestCase10, YES, 1718) | AK14: correct | AL14: 1 | AM14: 10/10 | AP14: 1 | AQ14: 10/10 | AR14: 17612 | AS14: 1761.2 | AT14: 1724.5 | AU14: Bit Calculation
B15: Incorrect_Bit_Calculation_2_NT.c | C15: (FSE_Bitvector_Mode_Incorrect_Bit_Calculation_2_NT_Loop0_TestCase0, NO, 1805) | D15: correct | E15: 0 | F15: 0/0 | G15: 1 | H15: 1/1 | I15: 1 | J15: 1/1 | K15: 1805 | L15: 1805 | M15: 1805 | N15: (FSE_Bitvector_Mode_Incorrect_Bit_Calculation_2_NT_Loop20_TestCase0, NO, 1789) | O15: correct | P15: 0 | Q15: 0/0 | R15: 1 | S15: 1/1 | T15: 1 | U15: 1/1 | V15: 1789 | W15: 1789 | X15: 1789 | Y15: (FSE_Bitvector_Mode_Incorrect_Bit_Calculation_2_NT_Loop0_TestCase10, NO, 1742) (FSE_Bitvector_Mode_Incorrect_Bit_Calculation_2_NT_Loop0_TestCase4, YES, 6442) (FSE_Bitvector_Mode_Incorrect_Bit_Calculation_2_NT_Loop0_TestCase5, YES, 1732) (FSE_Bitvector_Mode_Incorrect_Bit_Calculation_2_NT_Loop0_TestCase7, NO, 1724) (FSE_Bitvector_Mode_Incorrect_Bit_Calculation_2_NT_Loop0_TestCase6, NO, 1707) (FSE_Bitvector_Mode_Incorrect_Bit_Calculation_2_NT_Loop0_TestCase2, YES, 1740) (FSE_Bitvector_Mode_Incorrect_Bit_Calculation_2_NT_Loop0_TestCase3, YES, 2966) (FSE_Bitvector_Mode_Incorrect_Bit_Calculation_2_NT_Loop0_TestCase1, YES, 1722) (FSE_Bitvector_Mode_Incorrect_Bit_Calculation_2_NT_Loop0_TestCase8, NO, 1734) (FSE_Bitvector_Mode_Incorrect_Bit_Calculation_2_NT_Loop0_TestCase9, NO, 1733) | Z15: correct | AA15: 1 | AB15: 5/5 | AC15: 1 | AD15: 5/5 | AE15: 1 | AF15: 10/10 | AG15: 23242 | AH15: 2324.2 | AI15: 1733.5 | AJ15: (FSE_Bitvector_Mode_Incorrect_Bit_Calculation_2_NT_Loop20_TestCase9, NO, 1743) (FSE_Bitvector_Mode_Incorrect_Bit_Calculation_2_NT_Loop20_TestCase8, NO, 1783) (FSE_Bitvector_Mode_Incorrect_Bit_Calculation_2_NT_Loop20_TestCase5, YES, 1832) (FSE_Bitvector_Mode_Incorrect_Bit_Calculation_2_NT_Loop20_TestCase4, YES, 5089) (FSE_Bitvector_Mode_Incorrect_Bit_Calculation_2_NT_Loop20_TestCase6, NO, 1841) (FSE_Bitvector_Mode_Incorrect_Bit_Calculation_2_NT_Loop20_TestCase7, NO, 1760) (FSE_Bitvector_Mode_Incorrect_Bit_Calculation_2_NT_Loop20_TestCase3, YES, 3419) (FSE_Bitvector_Mode_Incorrect_Bit_Calculation_2_NT_Loop20_TestCase10, NO, 1823) (FSE_Bitvector_Mode_Incorrect_Bit_Calculation_2_NT_Loop20_TestCase2, YES, 1808) (FSE_Bitvector_Mode_Incorrect_Bit_Calculation_2_NT_Loop20_TestCase1, YES, 1827) | AK15: correct | AL15: 1 | AM15: 5/5 | AN15: 1 | AO15: 5/5 | AP15: 1 | AQ15: 10/10 | AR15: 22925 | AS15: 2292.5 | AT15: 1825 | AU15: Bit Calculation
B16: Incorrect_Bit_Calculation_2_T.c | C16: (FSE_Bitvector_Mode_Incorrect_Bit_Calculation_2_T_Loop0_TestCase0, YES, 21009) | D16: correct | E16: 1 | F16: 1/1 | I16: 1 | J16: 1/1 | K16: 21009 | L16: 21009 | M16: 21009 | N16: (FSE_Bitvector_Mode_Incorrect_Bit_Calculation_2_T_Loop16_TestCase0, YES, 6934) | O16: correct | P16: 1 | Q16: 1/1 | T16: 1 | U16: 1/1 | V16: 6934 | W16: 6934 | X16: 6934 | Y16: (FSE_Bitvector_Mode_Incorrect_Bit_Calculation_2_T_Loop0_TestCase8, YES, 1725) (FSE_Bitvector_Mode_Incorrect_Bit_Calculation_2_T_Loop0_TestCase9, YES, 1737) (FSE_Bitvector_Mode_Incorrect_Bit_Calculation_2_T_Loop0_TestCase2, YES, 1709) (FSE_Bitvector_Mode_Incorrect_Bit_Calculation_2_T_Loop0_TestCase3, YES, 2400) (FSE_Bitvector_Mode_Incorrect_Bit_Calculation_2_T_Loop0_TestCase10, YES, 1719) (FSE_Bitvector_Mode_Incorrect_Bit_Calculation_2_T_Loop0_TestCase1, YES, 1719) (FSE_Bitvector_Mode_Incorrect_Bit_Calculation_2_T_Loop0_TestCase4, YES, 5393) (FSE_Bitvector_Mode_Incorrect_Bit_Calculation_2_T_Loop0_TestCase5, YES, 1717) (FSE_Bitvector_Mode_Incorrect_Bit_Calculation_2_T_Loop0_TestCase7, YES, 1774) (FSE_Bitvector_Mode_Incorrect_Bit_Calculation_2_T_Loop0_TestCase6, YES, 1729) | Z16: correct | AA16: 1 | AB16: 10/10 | AE16: 1 | AF16: 10/10 | AG16: 21622 | AH16: 2162.2 | AI16: 1727 | AJ16: (FSE_Bitvector_Mode_Incorrect_Bit_Calculation_2_T_Loop16_TestCase9, YES, 1792) (FSE_Bitvector_Mode_Incorrect_Bit_Calculation_2_T_Loop16_TestCase8, YES, 1784) (FSE_Bitvector_Mode_Incorrect_Bit_Calculation_2_T_Loop16_TestCase6, YES, 1779) (FSE_Bitvector_Mode_Incorrect_Bit_Calculation_2_T_Loop16_TestCase7, YES, 1758) (FSE_Bitvector_Mode_Incorrect_Bit_Calculation_2_T_Loop16_TestCase5, YES, 1926) (FSE_Bitvector_Mode_Incorrect_Bit_Calculation_2_T_Loop16_TestCase4, YES, 3716) (FSE_Bitvector_Mode_Incorrect_Bit_Calculation_2_T_Loop16_TestCase1, YES, 1770) (FSE_Bitvector_Mode_Incorrect_Bit_Calculation_2_T_Loop16_TestCase3, YES, 2961) (FSE_Bitvector_Mode_Incorrect_Bit_Calculation_2_T_Loop16_TestCase2, YES, 1784) (FSE_Bitvector_Mode_Incorrect_Bit_Calculation_2_T_Loop16_TestCase10, YES, 1738) | AK16: correct | AL16: 1 | AM16: 10/10 | AP16: 1 | AQ16: 10/10 | AR16: 21008 | AS16: 2100.8 | AT16: 1784 | AU16: Bit Calculation
B17: Incorrect_Bit_Calculation_3_NT.c | C17: (FSE_Bitvector_Mode_Incorrect_Bit_Calculation_3_NT_Loop0_TestCase0, NO, 1917) | D17: correct | E17: 0 | F17: 0/0 | G17: 1 | H17: 1/1 | I17: 1 | J17: 1/1 | K17: 1917 | L17: 1917 | M17: 1917 | N17: (FSE_Bitvector_Mode_Incorrect_Bit_Calculation_3_NT_Loop18_TestCase0, NO, 1747) | O17: correct | P17: 0 | Q17: 0/0 | R17: 1 | S17: 1/1 | T17: 1 | U17: 1/1 | V17: 1747 | W17: 1747 | X17: 1747 | Y17: (FSE_Bitvector_Mode_Incorrect_Bit_Calculation_3_NT_Loop0_TestCase1, YES, 1660) (FSE_Bitvector_Mode_Incorrect_Bit_Calculation_3_NT_Loop0_TestCase3, YES, 1744) (FSE_Bitvector_Mode_Incorrect_Bit_Calculation_3_NT_Loop0_TestCase2, YES, 1690) (FSE_Bitvector_Mode_Incorrect_Bit_Calculation_3_NT_Loop0_TestCase6, NO, 1718) (FSE_Bitvector_Mode_Incorrect_Bit_Calculation_3_NT_Loop0_TestCase7, NO, 1697) (FSE_Bitvector_Mode_Incorrect_Bit_Calculation_3_NT_Loop0_TestCase5, YES, 1677) (FSE_Bitvector_Mode_Incorrect_Bit_Calculation_3_NT_Loop0_TestCase4, YES, 1705) (FSE_Bitvector_Mode_Incorrect_Bit_Calculation_3_NT_Loop0_TestCase10, NO, 1680) (FSE_Bitvector_Mode_Incorrect_Bit_Calculation_3_NT_Loop0_TestCase9, NO, 1686) (FSE_Bitvector_Mode_Incorrect_Bit_Calculation_3_NT_Loop0_TestCase8, NO, 1692) | Z17: correct | AA17: 1 | AB17: 5/5 | AC17: 1 | AD17: 5/5 | AE17: 1 | AF17: 10/10 | AG17: 16949 | AH17: 1694.9 | AI17: 1691 | AJ17: (FSE_Bitvector_Mode_Incorrect_Bit_Calculation_3_NT_Loop18_TestCase10, NO, 1811) (FSE_Bitvector_Mode_Incorrect_Bit_Calculation_3_NT_Loop18_TestCase9, NO, 1713) (FSE_Bitvector_Mode_Incorrect_Bit_Calculation_3_NT_Loop18_TestCase8, NO, 1696) (FSE_Bitvector_Mode_Incorrect_Bit_Calculation_3_NT_Loop18_TestCase6, NO, 1693) (FSE_Bitvector_Mode_Incorrect_Bit_Calculation_3_NT_Loop18_TestCase7, NO, 1724) (FSE_Bitvector_Mode_Incorrect_Bit_Calculation_3_NT_Loop18_TestCase5, YES, 1785) (FSE_Bitvector_Mode_Incorrect_Bit_Calculation_3_NT_Loop18_TestCase4, YES, 1700) (FSE_Bitvector_Mode_Incorrect_Bit_Calculation_3_NT_Loop18_TestCase1, YES, 1722) (FSE_Bitvector_Mode_Incorrect_Bit_Calculation_3_NT_Loop18_TestCase3, YES, 1725) (FSE_Bitvector_Mode_Incorrect_Bit_Calculation_3_NT_Loop18_TestCase2, YES, 1697) | AK17: correct | AL17: 1 | AM17: 5/5 | AN17: 1 | AO17: 5/5 | AP17: 1 | AQ17: 10/10 | AR17: 17266 | AS17: 1726.6 | AT17: 1717.5 | AU17: Bit Calculation
B18: Incorrect_Bit_Calculation_3_T.c | C18: (FSE_Bitvector_Mode_Incorrect_Bit_Calculation_3_T_Loop0_TestCase0, YES, 1810) | D18: correct | E18: 1 | F18: 1/1 | I18: 1 | J18: 1/1 | K18: 1810 | L18: 1810 | M18: 1810 | N18: (FSE_Bitvector_Mode_Incorrect_Bit_Calculation_3_T_Loop15_TestCase0, YES, 1748) | O18: correct | P18: 1 | Q18: 1/1 | T18: 1 | U18: 1/1 | V18: 1748 | W18: 1748 | X18: 1748 | Y18: (FSE_Bitvector_Mode_Incorrect_Bit_Calculation_3_T_Loop0_TestCase1, YES, 1718) (FSE_Bitvector_Mode_Incorrect_Bit_Calculation_3_T_Loop0_TestCase2, YES, 1674) (FSE_Bitvector_Mode_Incorrect_Bit_Calculation_3_T_Loop0_TestCase3, YES, 1715) (FSE_Bitvector_Mode_Incorrect_Bit_Calculation_3_T_Loop0_TestCase7, YES, 1723) (FSE_Bitvector_Mode_Incorrect_Bit_Calculation_3_T_Loop0_TestCase6, YES, 1709) (FSE_Bitvector_Mode_Incorrect_Bit_Calculation_3_T_Loop0_TestCase4, YES, 1752) (FSE_Bitvector_Mode_Incorrect_Bit_Calculation_3_T_Loop0_TestCase5, YES, 1679) (FSE_Bitvector_Mode_Incorrect_Bit_Calculation_3_T_Loop0_TestCase8, YES, 1708) (FSE_Bitvector_Mode_Incorrect_Bit_Calculation_3_T_Loop0_TestCase9, YES, 1709) (FSE_Bitvector_Mode_Incorrect_Bit_Calculation_3_T_Loop0_TestCase10, YES, 1708) | Z18: correct | AA18: 1 | AB18: 10/10 | AE18: 1 | AF18: 10/10 | AG18: 17095 | AH18: 1709.5 | AI18: 1709 | AJ18: (FSE_Bitvector_Mode_Incorrect_Bit_Calculation_3_T_Loop15_TestCase10, YES, 1813) (FSE_Bitvector_Mode_Incorrect_Bit_Calculation_3_T_Loop15_TestCase8, YES, 1738) (FSE_Bitvector_Mode_Incorrect_Bit_Calculation_3_T_Loop15_TestCase9, YES, 1743) (FSE_Bitvector_Mode_Incorrect_Bit_Calculation_3_T_Loop15_TestCase7, YES, 1787) (FSE_Bitvector_Mode_Incorrect_Bit_Calculation_3_T_Loop15_TestCase6, YES, 1746) (FSE_Bitvector_Mode_Incorrect_Bit_Calculation_3_T_Loop15_TestCase4, YES, 1760) (FSE_Bitvector_Mode_Incorrect_Bit_Calculation_3_T_Loop15_TestCase5, YES, 1863) (FSE_Bitvector_Mode_Incorrect_Bit_Calculation_3_T_Loop15_TestCase1, YES, 1726) (FSE_Bitvector_Mode_Incorrect_Bit_Calculation_3_T_Loop15_TestCase2, YES, 1765) (FSE_Bitvector_Mode_Incorrect_Bit_Calculation_3_T_Loop15_TestCase3, YES, 1742) | AK18: correct | AL18: 1 | AM18: 10/10 | AP18: 1 | AQ18: 10/10 | AR18: 17683 | AS18: 1768.3 | AT18: 1753 | AU18: Bit Calculation
B19: Incorrect_Control_Statement_1_NT.c | C19: (FSE_Bitvector_Mode_Incorrect_Control_Statement_1_NT_Loop0_TestCase0, TIMEOUT, 302329) | D19: correct | E19: 0 | F19: 0/0 | G19: 0 | H19: 0/1 | I19: 0 | J19: 0/1 | K19: 0 | L19: 0 | M19: 0 | N19: (FSE_Bitvector_Mode_Incorrect_Control_Statement_1_NT_Loop16_TestCase0, YES, 2189) (FSE_Bitvector_Mode_Incorrect_Control_Statement_1_NT_Loop20_TestCase0, TIMEOUT, 302231) | O19: correct | P19: 1 | Q19: 1/1 | R19: 0 | S19: 0/1 | T19: 0.5 | U19: 1/2 | V19: 2189 | W19: 2189 | X19: 2189 | Y19: (FSE_Bitvector_Mode_Incorrect_Control_Statement_1_NT_Loop0_TestCase10, MAYBE, 1608) (FSE_Bitvector_Mode_Incorrect_Control_Statement_1_NT_Loop0_TestCase2, MAYBE, 1670) (FSE_Bitvector_Mode_Incorrect_Control_Statement_1_NT_Loop0_TestCase3, MAYBE, 1626) (FSE_Bitvector_Mode_Incorrect_Control_Statement_1_NT_Loop0_TestCase1, MAYBE, 1665) (FSE_Bitvector_Mode_Incorrect_Control_Statement_1_NT_Loop0_TestCase4, MAYBE, 1630) (FSE_Bitvector_Mode_Incorrect_Control_Statement_1_NT_Loop0_TestCase5, MAYBE, 1623) (FSE_Bitvector_Mode_Incorrect_Control_Statement_1_NT_Loop0_TestCase7, MAYBE, 1615) (FSE_Bitvector_Mode_Incorrect_Control_Statement_1_NT_Loop0_TestCase6, MAYBE, 1608) (FSE_Bitvector_Mode_Incorrect_Control_Statement_1_NT_Loop0_TestCase8, MAYBE, 1613) (FSE_Bitvector_Mode_Incorrect_Control_Statement_1_NT_Loop0_TestCase9, MAYBE, 1624) | Z19: correct | AA19: 0 | AB19: 0/5 | AC19: 0 | AD19: 0/5 | AE19: 0 | AF19: 0/10 | AG19: 0 | AH19: 0 | AI19: 0 | AJ19: (FSE_Bitvector_Mode_Incorrect_Control_Statement_1_NT_Loop20_TestCase9, MAYBE, 1646) (FSE_Bitvector_Mode_Incorrect_Control_Statement_1_NT_Loop20_TestCase8, MAYBE, 1626) (FSE_Bitvector_Mode_Incorrect_Control_Statement_1_NT_Loop16_TestCase10, ERROR, 1679) (FSE_Bitvector_Mode_Incorrect_Control_Statement_1_NT_Loop16_TestCase2, YES, 1743) (FSE_Bitvector_Mode_Incorrect_Control_Statement_1_NT_Loop16_TestCase3, ERROR, 1665) (FSE_Bitvector_Mode_Incorrect_Control_Statement_1_NT_Loop16_TestCase1, ERROR, 1707) (FSE_Bitvector_Mode_Incorrect_Control_Statement_1_NT_Loop16_TestCase4, ERROR, 1655) (FSE_Bitvector_Mode_Incorrect_Control_Statement_1_NT_Loop16_TestCase5, ERROR, 1631) (FSE_Bitvector_Mode_Incorrect_Control_Statement_1_NT_Loop16_TestCase7, ERROR, 1705) (FSE_Bitvector_Mode_Incorrect_Control_Statement_1_NT_Loop16_TestCase6, ERROR, 1678) (FSE_Bitvector_Mode_Incorrect_Control_Statement_1_NT_Loop16_TestCase8, YES, 1755) (FSE_Bitvector_Mode_Incorrect_Control_Statement_1_NT_Loop16_TestCase9, YES, 1837) (FSE_Bitvector_Mode_Incorrect_Control_Statement_1_NT_Loop20_TestCase10, MAYBE, 1659) (FSE_Bitvector_Mode_Incorrect_Control_Statement_1_NT_Loop20_TestCase1, MAYBE, 1644) (FSE_Bitvector_Mode_Incorrect_Control_Statement_1_NT_Loop20_TestCase3, MAYBE, 1641) (FSE_Bitvector_Mode_Incorrect_Control_Statement_1_NT_Loop20_TestCase2, MAYBE, 1626) (FSE_Bitvector_Mode_Incorrect_Control_Statement_1_NT_Loop20_TestCase6, MAYBE, 1667) (FSE_Bitvector_Mode_Incorrect_Control_Statement_1_NT_Loop20_TestCase7, MAYBE, 1623) (FSE_Bitvector_Mode_Incorrect_Control_Statement_1_NT_Loop20_TestCase5, MAYBE, 1683) (FSE_Bitvector_Mode_Incorrect_Control_Statement_1_NT_Loop20_TestCase4, MAYBE, 1683) | AK19: correct | AL19: 0.2 | AM19: 3/15 | AN19: 0 | AO19: 0/5 | AP19: 0.15 | AQ19: 3/20 | AR19: 5335 | AS19: 1778.33 | AT19: 1755 | AU19: Pointer + Array
B20: Incorrect_Control_Statement_1_T.c | C20: (FSE_Bitvector_Mode_Incorrect_Control_Statement_1_T_Loop0_TestCase0, TIMEOUT, 302544) | D20: correct | E20: 0 | F20: 0/1 | I20: 0 | J20: 0/1 | K20: 0 | L20: 0 | M20: 0 | N20: (FSE_Bitvector_Mode_Incorrect_Control_Statement_1_T_Loop14_TestCase0, YES, 2167) (FSE_Bitvector_Mode_Incorrect_Control_Statement_1_T_Loop18_TestCase0, TIMEOUT, 302260) | O20: correct | P20: 0.5 | Q20: 1/2 | T20: 0.5 | U20: 1/2 | V20: 2167 | W20: 2167 | X20: 2167 | Y20: (FSE_Bitvector_Mode_Incorrect_Control_Statement_1_T_Loop0_TestCase8, MAYBE, 1607) (FSE_Bitvector_Mode_Incorrect_Control_Statement_1_T_Loop0_TestCase9, MAYBE, 1601) (FSE_Bitvector_Mode_Incorrect_Control_Statement_1_T_Loop0_TestCase7, MAYBE, 1652) (FSE_Bitvector_Mode_Incorrect_Control_Statement_1_T_Loop0_TestCase6, MAYBE, 1646) (FSE_Bitvector_Mode_Incorrect_Control_Statement_1_T_Loop0_TestCase4, MAYBE, 1627) (FSE_Bitvector_Mode_Incorrect_Control_Statement_1_T_Loop0_TestCase5, MAYBE, 1630) (FSE_Bitvector_Mode_Incorrect_Control_Statement_1_T_Loop0_TestCase1, MAYBE, 1608) (FSE_Bitvector_Mode_Incorrect_Control_Statement_1_T_Loop0_TestCase10, MAYBE, 1622) (FSE_Bitvector_Mode_Incorrect_Control_Statement_1_T_Loop0_TestCase2, MAYBE, 1643) (FSE_Bitvector_Mode_Incorrect_Control_Statement_1_T_Loop0_TestCase3, MAYBE, 1642) | Z20: correct | AA20: 0 | AB20: 0/10 | AE20: 0 | AF20: 0/10 | AG20: 0 | AH20: 0 | AI20: 0 | AJ20: (FSE_Bitvector_Mode_Incorrect_Control_Statement_1_T_Loop18_TestCase9, MAYBE, 1678) (FSE_Bitvector_Mode_Incorrect_Control_Statement_1_T_Loop18_TestCase8, MAYBE, 1643) (FSE_Bitvector_Mode_Incorrect_Control_Statement_1_T_Loop14_TestCase2, YES, 1769) (FSE_Bitvector_Mode_Incorrect_Control_Statement_1_T_Loop14_TestCase3, ERROR, 1787) (FSE_Bitvector_Mode_Incorrect_Control_Statement_1_T_Loop14_TestCase1, ERROR, 1684) (FSE_Bitvector_Mode_Incorrect_Control_Statement_1_T_Loop14_TestCase4, ERROR, 1674) (FSE_Bitvector_Mode_Incorrect_Control_Statement_1_T_Loop14_TestCase5, ERROR, 1617) (FSE_Bitvector_Mode_Incorrect_Control_Statement_1_T_Loop14_TestCase7, ERROR, 1645) (FSE_Bitvector_Mode_Incorrect_Control_Statement_1_T_Loop14_TestCase6, ERROR, 1655) (FSE_Bitvector_Mode_Incorrect_Control_Statement_1_T_Loop14_TestCase8, YES, 1914) (FSE_Bitvector_Mode_Incorrect_Control_Statement_1_T_Loop14_TestCase9, YES, 1723) (FSE_Bitvector_Mode_Incorrect_Control_Statement_1_T_Loop14_TestCase10, ERROR, 1659) (FSE_Bitvector_Mode_Incorrect_Control_Statement_1_T_Loop18_TestCase5, MAYBE, 1669) (FSE_Bitvector_Mode_Incorrect_Control_Statement_1_T_Loop18_TestCase4, MAYBE, 1668) (FSE_Bitvector_Mode_Incorrect_Control_Statement_1_T_Loop18_TestCase6, MAYBE, 1660) (FSE_Bitvector_Mode_Incorrect_Control_Statement_1_T_Loop18_TestCase7, MAYBE, 1644) (FSE_Bitvector_Mode_Incorrect_Control_Statement_1_T_Loop18_TestCase3, MAYBE, 1672) (FSE_Bitvector_Mode_Incorrect_Control_Statement_1_T_Loop18_TestCase2, MAYBE, 1645) (FSE_Bitvector_Mode_Incorrect_Control_Statement_1_T_Loop18_TestCase10, MAYBE, 1643) (FSE_Bitvector_Mode_Incorrect_Control_Statement_1_T_Loop18_TestCase1, MAYBE, 1645) | AK20: correct | AL20: 0.15 | AM20: 3/20 | AP20: 0.15 | AQ20: 3/20 | AR20: 5406 | AS20: 1802 | AT20: 1769 | AU20: Pointer + Array
B21: Incorrect_Control_Statement_2_NT.c | C21: (FSE_Bitvector_Mode_Incorrect_Control_Statement_2_NT_Loop0_TestCase0, TIMEOUT, 302085) | D21: correct | E21: 0 | F21: 0/0 | G21: 0 | H21: 0/1 | I21: 0 | J21: 0/1 | K21: 0 | L21: 0 | M21: 0 | N21: (FSE_Bitvector_Mode_Incorrect_Control_Statement_2_NT_Loop23_TestCase0, TIMEOUT, 301752) (FSE_Bitvector_Mode_Incorrect_Control_Statement_2_NT_Loop17_TestCase0, YES, 1770) | O21: correct | P21: 1 | Q21: 1/1 | R21: 0 | S21: 0/1 | T21: 0.5 | U21: 1/2 | V21: 1770 | W21: 1770 | X21: 1770 | Y21: (FSE_Bitvector_Mode_Incorrect_Control_Statement_2_NT_Loop0_TestCase7, NO, 2826) (FSE_Bitvector_Mode_Incorrect_Control_Statement_2_NT_Loop0_TestCase6, NO, 4228) (FSE_Bitvector_Mode_Incorrect_Control_Statement_2_NT_Loop0_TestCase4, NO, 3270) (FSE_Bitvector_Mode_Incorrect_Control_Statement_2_NT_Loop0_TestCase10, NO, 3013) (FSE_Bitvector_Mode_Incorrect_Control_Statement_2_NT_Loop0_TestCase5, NO, 3785) (FSE_Bitvector_Mode_Incorrect_Control_Statement_2_NT_Loop0_TestCase1, NO, 4305) (FSE_Bitvector_Mode_Incorrect_Control_Statement_2_NT_Loop0_TestCase2, NO, 4215) (FSE_Bitvector_Mode_Incorrect_Control_Statement_2_NT_Loop0_TestCase3, NO, 3563) (FSE_Bitvector_Mode_Incorrect_Control_Statement_2_NT_Loop0_TestCase8, NO, 4156) (FSE_Bitvector_Mode_Incorrect_Control_Statement_2_NT_Loop0_TestCase9, NO, 2919) | Z21: correct | AA21: 0 | AB21: 0/5 | AC21: 1 | AD21: 5/5 | AE21: 0.5 | AF21: 5/10 | AG21: 17142 | AH21: 3428.4 | AI21: 3013 | AJ21: (FSE_Bitvector_Mode_Incorrect_Control_Statement_2_NT_Loop17_TestCase9, YES, 1749) (FSE_Bitvector_Mode_Incorrect_Control_Statement_2_NT_Loop17_TestCase8, YES, 1745) (FSE_Bitvector_Mode_Incorrect_Control_Statement_2_NT_Loop23_TestCase9, NO, 4385) (FSE_Bitvector_Mode_Incorrect_Control_Statement_2_NT_Loop23_TestCase8, NO, 2984) (FSE_Bitvector_Mode_Incorrect_Control_Statement_2_NT_Loop23_TestCase10, NO, 3535) (FSE_Bitvector_Mode_Incorrect_Control_Statement_2_NT_Loop23_TestCase1, NO, 4481) (FSE_Bitvector_Mode_Incorrect_Control_Statement_2_NT_Loop23_TestCase3, NO, 4150) (FSE_Bitvector_Mode_Incorrect_Control_Statement_2_NT_Loop23_TestCase2, NO, 2886) (FSE_Bitvector_Mode_Incorrect_Control_Statement_2_NT_Loop23_TestCase6, NO, 3186) (FSE_Bitvector_Mode_Incorrect_Control_Statement_2_NT_Loop17_TestCase10, YES, 1751) (FSE_Bitvector_Mode_Incorrect_Control_Statement_2_NT_Loop23_TestCase7, NO, 4314) (FSE_Bitvector_Mode_Incorrect_Control_Statement_2_NT_Loop23_TestCase5, NO, 4332) (FSE_Bitvector_Mode_Incorrect_Control_Statement_2_NT_Loop23_TestCase4, NO, 4183) (FSE_Bitvector_Mode_Incorrect_Control_Statement_2_NT_Loop17_TestCase1, YES, 1713) (FSE_Bitvector_Mode_Incorrect_Control_Statement_2_NT_Loop17_TestCase3, YES, 1742) (FSE_Bitvector_Mode_Incorrect_Control_Statement_2_NT_Loop17_TestCase2, YES, 1697) (FSE_Bitvector_Mode_Incorrect_Control_Statement_2_NT_Loop17_TestCase6, YES, 1745) (FSE_Bitvector_Mode_Incorrect_Control_Statement_2_NT_Loop17_TestCase7, YES, 1752) (FSE_Bitvector_Mode_Incorrect_Control_Statement_2_NT_Loop17_TestCase5, YES, 1757) (FSE_Bitvector_Mode_Incorrect_Control_Statement_2_NT_Loop17_TestCase4, YES, 1730) | AK21: correct | AL21: 0.6667 | AM21: 10/15 | AN21: 1 | AO21: 5/5 | AP21: 0.75 | AQ21: 15/20 | AR21: 35785 | AS21: 2385.67 | AT21: 1751 | AU21: Array
B22: Incorrect_Control_Statement_2_T.c | C22: (FSE_Bitvector_Mode_Incorrect_Control_Statement_2_T_Loop0_TestCase0, YES, 2274) | D22: correct | E22: 1 | F22: 1/1 | I22: 1 | J22: 1/1 | K22: 2274 | L22: 2274 | M22: 2274 | N22: (FSE_Bitvector_Mode_Incorrect_Control_Statement_2_T_Loop23_TestCase0, YES, 2415) (FSE_Bitvector_Mode_Incorrect_Control_Statement_2_T_Loop17_TestCase0, YES, 1827) | O22: correct | P22: 1 | Q22: 2/2 | T22: 1 | U22: 2/2 | V22: 4242 | W22: 2121 | X22: 2121 | Y22: (FSE_Bitvector_Mode_Incorrect_Control_Statement_2_T_Loop0_TestCase3, YES, 2191) (FSE_Bitvector_Mode_Incorrect_Control_Statement_2_T_Loop0_TestCase2, YES, 2063) (FSE_Bitvector_Mode_Incorrect_Control_Statement_2_T_Loop0_TestCase1, YES, 2103) (FSE_Bitvector_Mode_Incorrect_Control_Statement_2_T_Loop0_TestCase5, YES, 2122) (FSE_Bitvector_Mode_Incorrect_Control_Statement_2_T_Loop0_TestCase4, YES, 2025) (FSE_Bitvector_Mode_Incorrect_Control_Statement_2_T_Loop0_TestCase6, YES, 1973) (FSE_Bitvector_Mode_Incorrect_Control_Statement_2_T_Loop0_TestCase7, YES, 2066) (FSE_Bitvector_Mode_Incorrect_Control_Statement_2_T_Loop0_TestCase9, YES, 2069) (FSE_Bitvector_Mode_Incorrect_Control_Statement_2_T_Loop0_TestCase8, YES, 1930) (FSE_Bitvector_Mode_Incorrect_Control_Statement_2_T_Loop0_TestCase10, YES, 1967) | Z22: correct | AA22: 1 | AB22: 10/10 | AE22: 1 | AF22: 10/10 | AG22: 20509 | AH22: 2050.9 | AI22: 2064.5 | AJ22: (FSE_Bitvector_Mode_Incorrect_Control_Statement_2_T_Loop23_TestCase2, YES, 2418) (FSE_Bitvector_Mode_Incorrect_Control_Statement_2_T_Loop23_TestCase3, YES, 2080) (FSE_Bitvector_Mode_Incorrect_Control_Statement_2_T_Loop23_TestCase1, YES, 2206) (FSE_Bitvector_Mode_Incorrect_Control_Statement_2_T_Loop23_TestCase4, YES, 2074) (FSE_Bitvector_Mode_Incorrect_Control_Statement_2_T_Loop23_TestCase5, YES, 2234) (FSE_Bitvector_Mode_Incorrect_Control_Statement_2_T_Loop23_TestCase7, YES, 2114) (FSE_Bitvector_Mode_Incorrect_Control_Statement_2_T_Loop23_TestCase6, YES, 2087) (FSE_Bitvector_Mode_Incorrect_Control_Statement_2_T_Loop17_TestCase2, YES, 1726) (FSE_Bitvector_Mode_Incorrect_Control_Statement_2_T_Loop17_TestCase3, YES, 1752) (FSE_Bitvector_Mode_Incorrect_Control_Statement_2_T_Loop17_TestCase1, YES, 1740) (FSE_Bitvector_Mode_Incorrect_Control_Statement_2_T_Loop17_TestCase4, YES, 1756) (FSE_Bitvector_Mode_Incorrect_Control_Statement_2_T_Loop23_TestCase10, YES, 1999) (FSE_Bitvector_Mode_Incorrect_Control_Statement_2_T_Loop17_TestCase5, YES, 1762) (FSE_Bitvector_Mode_Incorrect_Control_Statement_2_T_Loop17_TestCase7, YES, 1712) (FSE_Bitvector_Mode_Incorrect_Control_Statement_2_T_Loop17_TestCase6, YES, 1773) (FSE_Bitvector_Mode_Incorrect_Control_Statement_2_T_Loop17_TestCase8, YES, 1718) (FSE_Bitvector_Mode_Incorrect_Control_Statement_2_T_Loop17_TestCase10, YES, 1754) (FSE_Bitvector_Mode_Incorrect_Control_Statement_2_T_Loop17_TestCase9, YES, 1764) (FSE_Bitvector_Mode_Incorrect_Control_Statement_2_T_Loop23_TestCase8, YES, 2091) (FSE_Bitvector_Mode_Incorrect_Control_Statement_2_T_Loop23_TestCase9, YES, 2135) | AK22: correct | AL22: 1 | AM22: 20/20 | AP22: 1 | AQ22: 20/20 | AR22: 38895 | AS22: 1944.75 | AT22: 1886 | AU22: Array
B23: Incorrect_Initialization_1_NT.c | C23: (FSE_Bitvector_Mode_Incorrect_Initialization_1_NT_Loop0_TestCase0, NO, 132055) | D23: correct | E23: 0 | F23: 0/0 | G23: 1 | H23: 1/1 | I23: 1 | J23: 1/1 | K23: 132055 | L23: 132055 | M23: 132055 | N23: (FSE_Bitvector_Mode_Incorrect_Initialization_1_NT_Loop19_TestCase0, NO, 298158) (FSE_Bitvector_Mode_Incorrect_Initialization_1_NT_Loop16_TestCase0, TIMEOUT, 302299) (FSE_Bitvector_Mode_Incorrect_Initialization_1_NT_Loop32_TestCase0, YES, 1767) (FSE_Bitvector_Mode_Incorrect_Initialization_1_NT_Loop36_TestCase0, TIMEOUT, 302357) | O23: correct | P23: 1 | Q23: 1/1 | R23: 0.3333 | S23: 1/3 | T23: 0.5 | U23: 2/4 | V23: 299925 | W23: 149962.5 | X23: 149962.5 | Y23: (FSE_Bitvector_Mode_Incorrect_Initialization_1_NT_Loop0_TestCase6, MAYBE, 1362) (FSE_Bitvector_Mode_Incorrect_Initialization_1_NT_Loop0_TestCase7, MAYBE, 1341) (FSE_Bitvector_Mode_Incorrect_Initialization_1_NT_Loop0_TestCase5, MAYBE, 1373) (FSE_Bitvector_Mode_Incorrect_Initialization_1_NT_Loop0_TestCase4, MAYBE, 1351) (FSE_Bitvector_Mode_Incorrect_Initialization_1_NT_Loop0_TestCase1, MAYBE, 1372) (FSE_Bitvector_Mode_Incorrect_Initialization_1_NT_Loop0_TestCase3, MAYBE, 1337) (FSE_Bitvector_Mode_Incorrect_Initialization_1_NT_Loop0_TestCase2, MAYBE, 1370) (FSE_Bitvector_Mode_Incorrect_Initialization_1_NT_Loop0_TestCase10, MAYBE, 1346) (FSE_Bitvector_Mode_Incorrect_Initialization_1_NT_Loop0_TestCase9, MAYBE, 1361) (FSE_Bitvector_Mode_Incorrect_Initialization_1_NT_Loop0_TestCase8, MAYBE, 1334) | Z23: correct | AA23: 0 | AB23: 0/1 | AC23: 0 | AD23: 0/9 | AE23: 0 | AF23: 0/10 | AG23: 0 | AH23: 0 | AI23: 0 | AJ23: (FSE_Bitvector_Mode_Incorrect_Initialization_1_NT_Loop19_TestCase5, MAYBE, 1397) (FSE_Bitvector_Mode_Incorrect_Initialization_1_NT_Loop19_TestCase4, MAYBE, 1364) (FSE_Bitvector_Mode_Incorrect_Initialization_1_NT_Loop32_TestCase9, ERROR, 1635) (FSE_Bitvector_Mode_Incorrect_Initialization_1_NT_Loop19_TestCase6, MAYBE, 1407) (FSE_Bitvector_Mode_Incorrect_Initialization_1_NT_Loop36_TestCase8, MAYBE, 1374) (FSE_Bitvector_Mode_Incorrect_Initialization_1_NT_Loop36_TestCase9, MAYBE, 1739) (FSE_Bitvector_Mode_Incorrect_Initialization_1_NT_Loop19_TestCase7, MAYBE, 1375) (FSE_Bitvector_Mode_Incorrect_Initialization_1_NT_Loop32_TestCase8, YES, 1754) (FSE_Bitvector_Mode_Incorrect_Initialization_1_NT_Loop19_TestCase3, MAYBE, 1350) (FSE_Bitvector_Mode_Incorrect_Initialization_1_NT_Loop32_TestCase10, YES, 1846) (FSE_Bitvector_Mode_Incorrect_Initialization_1_NT_Loop19_TestCase2, MAYBE, 1387) (FSE_Bitvector_Mode_Incorrect_Initialization_1_NT_Loop19_TestCase1, MAYBE, 1354) (FSE_Bitvector_Mode_Incorrect_Initialization_1_NT_Loop16_TestCase8, MAYBE, 1390) (FSE_Bitvector_Mode_Incorrect_Initialization_1_NT_Loop16_TestCase9, MAYBE, 1382) (FSE_Bitvector_Mode_Incorrect_Initialization_1_NT_Loop36_TestCase10, MAYBE, 1372) (FSE_Bitvector_Mode_Incorrect_Initialization_1_NT_Loop16_TestCase7, MAYBE, 1359) (FSE_Bitvector_Mode_Incorrect_Initialization_1_NT_Loop16_TestCase6, MAYBE, 1383) (FSE_Bitvector_Mode_Incorrect_Initialization_1_NT_Loop16_TestCase4, MAYBE, 1353) (FSE_Bitvector_Mode_Incorrect_Initialization_1_NT_Loop16_TestCase5, MAYBE, 1416) (FSE_Bitvector_Mode_Incorrect_Initialization_1_NT_Loop16_TestCase1, MAYBE, 1374) (FSE_Bitvector_Mode_Incorrect_Initialization_1_NT_Loop19_TestCase10, MAYBE, 1398) (FSE_Bitvector_Mode_Incorrect_Initialization_1_NT_Loop16_TestCase10, MAYBE, 1337) (FSE_Bitvector_Mode_Incorrect_Initialization_1_NT_Loop16_TestCase2, MAYBE, 1393) (FSE_Bitvector_Mode_Incorrect_Initialization_1_NT_Loop16_TestCase3, MAYBE, 1365) (FSE_Bitvector_Mode_Incorrect_Initialization_1_NT_Loop32_TestCase3, YES, 1829) (FSE_Bitvector_Mode_Incorrect_Initialization_1_NT_Loop36_TestCase2, MAYBE, 1380) (FSE_Bitvector_Mode_Incorrect_Initialization_1_NT_Loop36_TestCase3, MAYBE, 1346) (FSE_Bitvector_Mode_Incorrect_Initialization_1_NT_Loop32_TestCase2, YES, 1914) (FSE_Bitvector_Mode_Incorrect_Initialization_1_NT_Loop36_TestCase1, MAYBE, 1358) (FSE_Bitvector_Mode_Incorrect_Initialization_1_NT_Loop32_TestCase1, YES, 1824) (FSE_Bitvector_Mode_Incorrect_Initialization_1_NT_Loop32_TestCase5, YES, 1826) (FSE_Bitvector_Mode_Incorrect_Initialization_1_NT_Loop36_TestCase4, MAYBE, 1361) (FSE_Bitvector_Mode_Incorrect_Initialization_1_NT_Loop36_TestCase5, MAYBE, 1374) (FSE_Bitvector_Mode_Incorrect_Initialization_1_NT_Loop32_TestCase4, ERROR, 1845) (FSE_Bitvector_Mode_Incorrect_Initialization_1_NT_Loop32_TestCase6, ERROR, 1915) (FSE_Bitvector_Mode_Incorrect_Initialization_1_NT_Loop19_TestCase9, MAYBE, 1345) (FSE_Bitvector_Mode_Incorrect_Initialization_1_NT_Loop36_TestCase7, MAYBE, 1387) (FSE_Bitvector_Mode_Incorrect_Initialization_1_NT_Loop36_TestCase6, MAYBE, 1369) (FSE_Bitvector_Mode_Incorrect_Initialization_1_NT_Loop19_TestCase8, MAYBE, 1391) (FSE_Bitvector_Mode_Incorrect_Initialization_1_NT_Loop32_TestCase7, ERROR, 1788) | AK23: correct | AL23: 0.4615 | AM23: 6/13 | AN23: 0 | AO23: 0/27 | AP23: 0.15 | AQ23: 6/40 | AR23: 10993 | AS23: 1832.17 | AT23: 1827.5 | AU23: Pointer + Array
